Workbook
Name Slicer_Representative: #N/A

Sheet Sheet3
A1: Data returned for total duration (First 1000 rows).
A3: calls[Call number] | B3: calls[Customer ID] | C3: calls[Duration] | D3: calls[Representative] | E3: calls[Date of Call] | F3: calls[Purchase Amount] | G3: calls[Satisfaction Rating] | H3: calls[FY] | I3: calls[Day of week] | J3: calls[Duration Bucket] | K3: calls[Rating rounded]
A4: Call_7271 | B4: C0003 | C4: 116 | D4: R05 | E4: 44927 | F4: 128 | G4: 4.9 | H4: 2023 | I4: Sunday | J4: 1 to 2 hours | K4: 5
A5: Call_7272 | B5: C0004 | C5: 119 | D5: R05 | E5: 44927 | F5: 135 | G5: 2.9 | H5: 2023 | I5: Sunday | J5: 1 to 2 hours | K5: 3
A6: Call_7273 | B6: C0005 | C6: 68 | D6: R02 | E6: 44927 | F6: 66 | G6: 4.7 | H6: 2023 | I6: Sunday | J6: 1 to 2 hours | K6: 5
A7: Call_7274 | B7: C0014 | C7: 119 | D7: R02 | E7: 44927 | F7: 22 | G7: 2.9 | H7: 2023 | I7: Sunday | J7: 1 to 2 hours | K7: 3
A8: Call_7275 | B8: C0011 | C8: 128 | D8: R01 | E8: 44928 | F8: 31 | G8: 2.8 | H8: 2023 | I8: Monday | J8: More than 2 hours | K8: 3
A9: Call_7276 | B9: C0011 | C9: 49 | D9: R02 | E9: 44929 | F9: 135 | G9: 4.8 | H9: 2023 | I9: Tuesday | J9: 30 to 60 mins | K9: 5
A10: Call_7277 | B10: C0007 | C10: 84 | D10: R05 | E10: 44929 | F10: 60 | G10: 4.7 | H10: 2023 | I10: Tuesday | J10: 1 to 2 hours | K10: 5
A11: Call_7278 | B11: C0003 | C11: 103 | D11: R04 | E11: 44929 | F11: 148 | G11: 4.4 | H11: 2023 | I11: Tuesday | J11: 1 to 2 hours | K11: 4
A12: Call_7279 | B12: C0005 | C12: 31 | D12: R02 | E12: 44929 | F12: 135 | G12: 3.6 | H12: 2023 | I12: Tuesday | J12: 30 to 60 mins | K12: 4
A13: Call_7280 | B13: C0010 | C13: 44 | D13: R03 | E13: 44929 | F13: 105 | G13: 2.9 | H13: 2023 | I13: Tuesday | J13: 30 to 60 mins | K13: 3
A14: Call_7281 | B14: C0011 | C14: 102 | D14: R02 | E14: 44929 | F14: 69 | G14: 4.9 | H14: 2023 | I14: Tuesday | J14: 1 to 2 hours | K14: 5
A15: Call_7282 | B15: C0013 | C15: 135 | D15: R05 | E15: 44929 | F15: 46 | G15: 3.4 | H15: 2023 | I15: Tuesday | J15: More than 2 hours | K15: 3
... A1003: Call_8270 | B1003: C0009 | C1003: 114 | D1003: R01 | E1003: 45291 | F1003: 40 | G1003: 3.9 | H1003: 2024 | I1003: Sunday | J1003: 1 to 2 hours | K1003: 4

Sheet Sheet4
A1: Data returned for CALL COUNT (First 1000 rows).
A3: calls[Call number] | B3: calls[Customer ID] | C3: calls[Duration] | D3: calls[Representative] | E3: calls[Date of Call] | F3: calls[Purchase Amount] | G3: calls[Satisfaction Rating] | H3: calls[FY] | I3: calls[Day of week] | J3: calls[Duration Bucket] | K3: calls[Rating rounded]
A4: Call_7271 | B4: C0003 | C4: 116 | D4: R05 | E4: 44927 | F4: 128 | G4: 4.9 | H4: 2023 | I4: Sunday | J4: 1 to 2 hours | K4: 5
A5: Call_7272 | B5: C0004 | C5: 119 | D5: R05 | E5: 44927 | F5: 135 | G5: 2.9 | H5: 2023 | I5: Sunday | J5: 1 to 2 hours | K5: 3
A6: Call_7273 | B6: C0005 | C6: 68 | D6: R02 | E6: 44927 | F6: 66 | G6: 4.7 | H6: 2023 | I6: Sunday | J6: 1 to 2 hours | K6: 5
A7: Call_7274 | B7: C0014 | C7: 119 | D7: R02 | E7: 44927 | F7: 22 | G7: 2.9 | H7: 2023 | I7: Sunday | J7: 1 to 2 hours | K7: 3
A8: Call_7275 | B8: C0011 | C8: 128 | D8: R01 | E8: 44928 | F8: 31 | G8: 2.8 | H8: 2023 | I8: Monday | J8: More than 2 hours | K8: 3
A9: Call_7276 | B9: C0011 | C9: 49 | D9: R02 | E9: 44929 | F9: 135 | G9: 4.8 | H9: 2023 | I9: Tuesday | J9: 30 to 60 mins | K9: 5
A10: Call_7277 | B10: C0007 | C10: 84 | D10: R05 | E10: 44929 | F10: 60 | G10: 4.7 | H10: 2023 | I10: Tuesday | J10: 1 to 2 hours | K10: 5
A11: Call_7278 | B11: C0003 | C11: 103 | D11: R04 | E11: 44929 | F11: 148 | G11: 4.4 | H11: 2023 | I11: Tuesday | J11: 1 to 2 hours | K11: 4
A12: Call_7279 | B12: C0005 | C12: 31 | D12: R02 | E12: 44929 | F12: 135 | G12: 3.6 | H12: 2023 | I12: Tuesday | J12: 30 to 60 mins | K12: 4
A13: Call_7280 | B13: C0010 | C13: 44 | D13: R03 | E13: 44929 | F13: 105 | G13: 2.9 | H13: 2023 | I13: Tuesday | J13: 30 to 60 mins | K13: 3
A14: Call_7281 | B14: C0011 | C14: 102 | D14: R02 | E14: 44929 | F14: 69 | G14: 4.9 | H14: 2023 | I14: Tuesday | J14: 1 to 2 hours | K14: 5
A15: Call_7282 | B15: C0013 | C15: 135 | D15: R05 | E15: 44929 | F15: 46 | G15: 3.4 | H15: 2023 | I15: Tuesday | J15: More than 2 hours | K15: 3
... A1003: Call_8270 | B1003: C0009 | C1003: 114 | D1003: R01 | E1003: 45291 | F1003: 40 | G1003: 3.9 | H1003: 2024 | I1003: Sunday | J1003: 1 to 2 hours | K1003: 4

Sheet Sheet2
A3: Call Count | B3: total amount | C3: total duration | D3: avg rating | E3: 5 star calls
A4: 1000 | B4: 96623 | C4: 89850 | D4: 3.8854 | E4: 307
A11: Call Count | B11: total amount | C11: total duration | D11: avg rating | E11: 5 star calls
A12: 200 | B12: 20104 | C12: 18209 | D12: 3.8825 | E12: 51
A17: Row Labels | B17: Call Count2 | C17: Call Count
A18: Jan | B18: 21 | C18: 21 | E18: Row Labels | F18: Call Count
A19: Feb | B19: 18 | C19: 18 | E19: Sunday | F19: 27
A20: Mar | B20: 31 | C20: 31 | E20: Monday | F20: 22
A21: Apr | B21: 20 | C21: 20 | E21: Tuesday | F21: 27
A22: May | B22: 8 | C22: 8 | E22: Wednesday | F22: 27
A23: Jun | B23: 12 | C23: 12 | E23: Thursday | F23: 27
A24: Jul | B24: 12 | C24: 12 | E24: Friday | F24: 32
A25: Aug | B25: 7 | C25: 7 | E25: Saturday | F25: 38
A26: Sep | B26: 20 | C26: 20 | E26: Grand Total | F26: 200
A27: Oct | B27: 24 | C27: 24
A28: Nov | B28: 12 | C28: 12
A29: Dec | B29: 15 | C29: 15
A30: Grand Total | B30: 200 | C30: 200
F33: for graph
A34: Row Labels | B34: total amount | C34: Call Count | J34: selected rep | K34: =F47 -> R05
A35: R01 | B35: 18415 | C35: 189
A36: R02 | B36: 20581 | C36: 218 | G36: rep | H36: amount | I36: calls | J36: sel.calls | K36: sel.amount
A37: R03 | B37: 20872 | C37: 207 | G37: {=A35:C39} -> R01 | H37: 18415 | I37: 189 | J37: =IF(G37=$K$34,I37,NA()) -> #N/A | K37: =IF(G37=$K$34,H37,NA()) -> #N/A
A38: R04 | B38: 16651 | C38: 186 | G38: R02 | H38: 20581 | I38: 218 | J38: =IF(G38=$K$34,I38,NA()) -> #N/A | K38: =IF(G38=$K$34,H38,NA()) -> #N/A
A39: R05 | B39: 20104 | C39: 200 | G39: R03 | H39: 20872 | I39: 207 | J39: =IF(G39=$K$34,I39,NA()) -> #N/A | K39: =IF(G39=$K$34,H39,NA()) -> #N/A
A40: Grand Total | B40: 96623 | C40: 1000 | G40: R04 | H40: 16651 | I40: 186 | J40: =IF(G40=$K$34,I40,NA()) -> #N/A | K40: =IF(G40=$K$34,H40,NA()) -> #N/A
G41: R05 | H41: 20104 | I41: 200 | J41: =IF(G41=$K$34,I41,NA()) -> 200 | K41: =IF(G41=$K$34,H41,NA()) -> 20104
F46: Row Labels
F47: R05
J48: Call Count | K48: Column Labels
J49: Row Labels | K49: Female | L49: Male | M49: Grand Total
J50: Cincinnati | K50: 144 | L50: 132 | M50: 276
J51: Cleveland | K51: 326 | L51: 63 | M51: 389
J52: Columbus | K52: 129 | L52: 206 | M52: 335
J53: Grand Total | K53: 599 | L53: 401 | M53: 1000
G57: Row Labels | H57: Call Count | S57: rep summary
G58: 2 | H58: 10 | J58: total amount | K58: Column Labels | S58: % of calls | T58: =GETPIVOTDATA("[Measures].[Call Count]",$A$11) -> 200
G59: 3 | H59: 44 | J59: Row Labels | K59: R01 | L59: R02 | M59: R03 | N59: R04 | O59: R05 | P59: Grand Total | S59: calls | T59: =_xlfn.XLOOKUP(F47,G37:G41,I37:I41) -> 200
G60: 4 | H60: 95 | J60: Cincinnati | S60: amount | T60: =_xlfn.XLOOKUP(F47,G37:G41,H37:H41) -> 20104
G61: 5 | H61: 51 | J61: C0003 | K61: 891 | L61: 1332 | M61: 1282 | N61: 739 | O61: 560 | P61: 4804
...

Sheet Sheet1
C1: call center report -2023
T24: =Sheet2!J60 -> Cincinnati | U24: R1 | V24: R2 | W24: R3 | X24: R4 | Y24: R5 | Z24: Total
T25: =Sheet2!J61 -> C0003 | U25: =Sheet2!K61 -> 891 | V25: =Sheet2!L61 -> 1332 | W25: =Sheet2!M61 -> 1282 | X25: =Sheet2!N61 -> 739 | Y25: =Sheet2!O61 -> 560 | Z25: =Sheet2!P61 -> 4804
T26: =Sheet2!J62 -> C0004 | U26: =Sheet2!K62 -> 1991 | V26: =Sheet2!L62 -> 1886 | W26: =Sheet2!M62 -> 1206 | X26: =Sheet2!N62 -> 884 | Y26: =Sheet2!O62 -> 1722 | Z26: =Sheet2!P62 -> 7689
T27: =Sheet2!J63 -> C0011 | U27: =Sheet2!K63 -> 1163 | V27: =Sheet2!L63 -> 1180 | W27: =Sheet2!M63 -> 1616 | X27: =Sheet2!N63 -> 1043 | Y27: =Sheet2!O63 -> 1747 | Z27: =Sheet2!P63 -> 6749
T28: =Sheet2!J64 -> C0012 | U28: =Sheet2!K64 -> 1438 | V28: =Sheet2!L64 -> 1616 | W28: =Sheet2!M64 -> 866 | X28: =Sheet2!N64 -> 829 | Y28: =Sheet2!O64 -> 2070 | Z28: =Sheet2!P64 -> 6819
T29: =Sheet2!J65 -> Cleveland
T30: =Sheet2!J66 -> C0002 | U30: =Sheet2!K66 -> 1233 | V30: =Sheet2!L66 -> 223 | W30: =Sheet2!M66 -> 1680 | X30: =Sheet2!N66 -> 990 | Y30: =Sheet2!O66 -> 1508 | Z30: =Sheet2!P66 -> 5634
T31: =Sheet2!J67 -> C0007 | U31: =Sheet2!K67 -> 1598 | V31: =Sheet2!L67 -> 1907 | W31: =Sheet2!M67 -> 869 | X31: =Sheet2!N67 -> 1426 | Y31: =Sheet2!O67 -> 1416 | Z31: =Sheet2!P67 -> 7216
T32: =Sheet2!J68 -> C0008 | U32: =Sheet2!K68 -> 900 | V32: =Sheet2!L68 -> 1016 | W32: =Sheet2!M68 -> 960 | X32: =Sheet2!N68 -> 940 | Y32: =Sheet2!O68 -> 1193 | Z32: =Sheet2!P68 -> 5009
T33: =Sheet2!J69 -> C0010 | U33: =Sheet2!K69 -> 900 | V33: =Sheet2!L69 -> 1470 | W33: =Sheet2!M69 -> 1617 | X33: =Sheet2!N69 -> 1314 | Y33: =Sheet2!O69 -> 941 | Z33: =Sheet2!P69 -> 6242
T34: =Sheet2!J70 -> C0013 | U34: =Sheet2!K70 -> 1255 | V34: =Sheet2!L70 -> 516 | W34: =Sheet2!M70 -> 1874 | X34: =Sheet2!N70 -> 1863 | Y34: =Sheet2!O70 -> 1722 | Z34: =Sheet2!P70 -> 7230
T35: =Sheet2!J71 -> C0015 | U35: =Sheet2!K71 -> 1138 | V35: =Sheet2!L71 -> 1898 | W35: =Sheet2!M71 -> 1482 | X35: =Sheet2!N71 -> 846 | Y35: =Sheet2!O71 -> 1154 | Z35: =Sheet2!P71 -> 6518
T36: =Sheet2!J72 -> Columbus
T37: =Sheet2!J73 -> C0001 | U37: =Sheet2!K73 -> 1655 | V37: =Sheet2!L73 -> 805 | W37: =Sheet2!M73 -> 2263 | X37: =Sheet2!N73 -> 987 | Y37: =Sheet2!O73 -> 1075 | Z37: =Sheet2!P73 -> 6785
T38: =Sheet2!J74 -> C0005 | U38: =Sheet2!K74 -> 1104 | V38: =Sheet2!L74 -> 2280 | W38: =Sheet2!M74 -> 1445 | X38: =Sheet2!N74 -> 1722 | Y38: =Sheet2!O74 -> 1196 | Z38: =Sheet2!P74 -> 7747
T39: =Sheet2!J75 -> C0006 | U39: =Sheet2!K75 -> 372 | V39: =Sheet2!L75 -> 1818 | W39: =Sheet2!M75 -> 1346 | X39: =Sheet2!N75 -> 1156 | Y39: =Sheet2!O75 -> 1484 | Z39: =Sheet2!P75 -> 6176
T40: =Sheet2!J76 -> C0009 | U40: =Sheet2!K76 -> 1415 | V40: =Sheet2!L76 -> 1271 | W40: =Sheet2!M76 -> 1214 | X40: =Sheet2!N76 -> 1135 | Y40: =Sheet2!O76 -> 1566 | Z40: =Sheet2!P76 -> 6601
T41: =Sheet2!J77 -> C0014 | U41: =Sheet2!K77 -> 1362 | V41: =Sheet2!L77 -> 1363 | W41: =Sheet2!M77 -> 1152 | X41: =Sheet2!N77 -> 777 | Y41: =Sheet2!O77 -> 750 | Z41: =Sheet2!P77 -> 5404
T42: =Sheet2!J78 -> Grand Total | U42: =Sheet2!K78 -> 18415 | V42: =Sheet2!L78 -> 20581 | W42: =Sheet2!M78 -> 20872 | X42: =Sheet2!N78 -> 16651 | Y42: =Sheet2!O78 -> 20104 | Z42: =Sheet2!P78 -> 96623

Sheet Assets
E2: Rep ID | F2: Rep Image
E3: R01 | F3: #VALUE!
E4: R02 | F4: #VALUE!
E5: R03 | F5: #VALUE!
E6: R04 | F6: #VALUE!
E7: R05 | F7: #VALUE!

Sheet Data
B1: Call Centre Data
B3: Call number | C3: Customer ID | D3: Duration | E3: Representative | F3: Date of Call | G3: Purchase Amount | H3: Satisfaction Rating | I3: FY | J3: Day of week | K3: Duration Bucket | L3: Rating rounded | Q3: Customer ID | R3: Gedner | S3: Age | T3: City
B4: Call_7271 | C4: C0003 | D4: 116 | E4: R05 | F4: 44927 | G4: 128 | H4: 4.9 | I4: =IF(MONTH(calls[[#This Row],[Date of Call]])<=6, YEAR(calls[[#This Row],[Date of Call]]), YEAR(calls[[#This Row],[Date of Call]])+1) -> 2023 | J4: =TEXT(calls[[#This Row],[Date of Call]],"DDDD") -> Sunday | K4: {=_xlfn.IFS(calls[[#This Row],[Duration]]<=10,"Under 10 mins", calls[[#This Row],[Duration]]<=30, "10 to 30 mins", calls[[#This Row],[Duration]]<=60, "30 to 60 mins", calls[[#This Row],[Duration]]<=120, "1 to 2 hours", TRUE, "More than 2 hours")} -> 1 to 2 hours | L4: =ROUND(calls[[#This Row],[Satisfaction Rating]],0) -> 5 | Q4: C0001 | R4: Male | S4: 41 | T4: Columbus
B5: Call_7272 | C5: C0004 | D5: 119 | E5: R05 | F5: 44927 | G5: 135 | H5: 2.9 | I5: =IF(MONTH(calls[[#This Row],[Date of Call]])<=6, YEAR(calls[[#This Row],[Date of Call]]), YEAR(calls[[#This Row],[Date of Call]])+1) -> 2023 | J5: =TEXT(calls[[#This Row],[Date of Call]],"DDDD") -> Sunday | K5: {=_xlfn.IFS(calls[[#This Row],[Duration]]<=10,"Under 10 mins", calls[[#This Row],[Duration]]<=30, "10 to 30 mins", calls[[#This Row],[Duration]]<=60, "30 to 60 mins", calls[[#This Row],[Duration]]<=120, "1 to 2 hours", TRUE, "More than 2 hours")} -> 1 to 2 hours | L5: =ROUND(calls[[#This Row],[Satisfaction Rating]],0) -> 3 | Q5: C0002 | R5: Male | S5: 31 | T5: Cleveland
B6: Call_7273 | C6: C0005 | D6: 68 | E6: R02 | F6: 44927 | G6: 66 | H6: 4.7 | I6: =IF(MONTH(calls[[#This Row],[Date of Call]])<=6, YEAR(calls[[#This Row],[Date of Call]]), YEAR(calls[[#This Row],[Date of Call]])+1) -> 2023 | J6: =TEXT(calls[[#This Row],[Date of Call]],"DDDD") -> Sunday | K6: {=_xlfn.IFS(calls[[#This Row],[Duration]]<=10,"Under 10 mins", calls[[#This Row],[Duration]]<=30, "10 to 30 mins", calls[[#This Row],[Duration]]<=60, "30 to 60 mins", calls[[#This Row],[Duration]]<=120, "1 to 2 hours", TRUE, "More than 2 hours")} -> 1 to 2 hours | L6: =ROUND(calls[[#This Row],[Satisfaction Rating]],0) -> 5 | Q6: C0003 | R6: Male | S6: 26 | T6: Cincinnati
B7: Call_7274 | C7: C0014 | D7: 119 | E7: R02 | F7: 44927 | G7: 22 | H7: 2.9 | I7: =IF(MONTH(calls[[#This Row],[Date of Call]])<=6, YEAR(calls[[#This Row],[Date of Call]]), YEAR(calls[[#This Row],[Date of Call]])+1) -> 2023 | J7: =TEXT(calls[[#This Row],[Date of Call]],"DDDD") -> Sunday | K7: {=_xlfn.IFS(calls[[#This Row],[Duration]]<=10,"Under 10 mins", calls[[#This Row],[Duration]]<=30, "10 to 30 mins", calls[[#This Row],[Duration]]<=60, "30 to 60 mins", calls[[#This Row],[Duration]]<=120, "1 to 2 hours", TRUE, "More than 2 hours")} -> 1 to 2 hours | L7: =ROUND(calls[[#This Row],[Satisfaction Rating]],0) -> 3 | Q7: C0004 | R7: Male | S7: 36 | T7: Cincinnati
B8: Call_7275 | C8: C0011 | D8: 128 | E8: R01 | F8: 44928 | G8: 31 | H8: 2.8 | I8: =IF(MONTH(calls[[#This Row],[Date of Call]])<=6, YEAR(calls[[#This Row],[Date of Call]]), YEAR(calls[[#This Row],[Date of Call]])+1) -> 2023 | J8: =TEXT(calls[[#This Row],[Date of Call]],"DDDD") -> Monday | K8: {=_xlfn.IFS(calls[[#This Row],[Duration]]<=10,"Under 10 mins", calls[[#This Row],[Duration]]<=30, "10 to 30 mins", calls[[#This Row],[Duration]]<=60, "30 to 60 mins", calls[[#This Row],[Duration]]<=120, "1 to 2 hours", TRUE, "More than 2 hours")} -> More than 2 hours | L8: =ROUND(calls[[#This Row],[Satisfaction Rating]],0) -> 3 | Q8: C0005 | R8: Male | S8: 37 | T8: Columbus
B9: Call_7276 | C9: C0011 | D9: 49 | E9: R02 | F9: 44929 | G9: 135 | H9: 4.8 | I9: =IF(MONTH(calls[[#This Row],[Date of Call]])<=6, YEAR(calls[[#This Row],[Date of Call]]), YEAR(calls[[#This Row],[Date of Call]])+1) -> 2023 | J9: =TEXT(calls[[#This Row],[Date of Call]],"DDDD") -> Tuesday | K9: {=_xlfn.IFS(calls[[#This Row],[Duration]]<=10,"Under 10 mins", calls[[#This Row],[Duration]]<=30, "10 to 30 mins", calls[[#This Row],[Duration]]<=60, "30 to 60 mins", calls[[#This Row],[Duration]]<=120, "1 to 2 hours", TRUE, "More than 2 hours")} -> 30 to 60 mins | L9: =ROUND(calls[[#This Row],[Satisfaction Rating]],0) -> 5 | Q9: C0006 | R9: Male | S9: 23 | T9: Columbus
B10: Call_7277 | C10: C0007 | D10: 84 | E10: R05 | F10: 44929 | G10: 60 | H10: 4.7 | I10: =IF(MONTH(calls[[#This Row],[Date of Call]])<=6, YEAR(calls[[#This Row],[Date of Call]]), YEAR(calls[[#This Row],[Date of Call]])+1) -> 2023 | J10: =TEXT(calls[[#This Row],[Date of Call]],"DDDD") -> Tuesday | K10: {=_xlfn.IFS(calls[[#This Row],[Duration]]<=10,"Under 10 mins", calls[[#This Row],[Duration]]<=30, "10 to 30 mins", calls[[#This Row],[Duration]]<=60, "30 to 60 mins", calls[[#This Row],[Duration]]<=120, "1 to 2 hours", TRUE, "More than 2 hours")} -> 1 to 2 hours | L10: =ROUND(calls[[#This Row],[Satisfaction Rating]],0) -> 5 | Q10: C0007 | R10: Female | S10: 22 | T10: Cleveland
B11: Call_7278 | C11: C0003 | D11: 103 | E11: R04 | F11: 44929 | G11: 148 | H11: 4.4 | I11: =IF(MONTH(calls[[#This Row],[Date of Call]])<=6, YEAR(calls[[#This Row],[Date of Call]]), YEAR(calls[[#This Row],[Date of Call]])+1) -> 2023 | J11: =TEXT(calls[[#This Row],[Date of Call]],"DDDD") -> Tuesday | K11: {=_xlfn.IFS(calls[[#This Row],[Duration]]<=10,"Under 10 mins", calls[[#This Row],[Duration]]<=30, "10 to 30 mins", calls[[#This Row],[Duration]]<=60, "30 to 60 mins", calls[[#This Row],[Duration]]<=120, "1 to 2 hours", TRUE, "More than 2 hours")} -> 1 to 2 hours | L11: =ROUND(calls[[#This Row],[Satisfaction Rating]],0) -> 4 | Q11: C0008 | R11: Female | S11: 42 | T11: Cleveland
B12: Call_7279 | C12: C0005 | D12: 31 | E12: R02 | F12: 44929 | G12: 135 | H12: 3.6 | I12: =IF(MONTH(calls[[#This Row],[Date of Call]])<=6, YEAR(calls[[#This Row],[Date of Call]]), YEAR(calls[[#This Row],[Date of Call]])+1) -> 2023 | J12: =TEXT(calls[[#This Row],[Date of Call]],"DDDD") -> Tuesday | K12: {=_xlfn.IFS(calls[[#This Row],[Duration]]<=10,"Under 10 mins", calls[[#This Row],[Duration]]<=30, "10 to 30 mins", calls[[#This Row],[Duration]]<=60, "30 to 60 mins", calls[[#This Row],[Duration]]<=120, "1 to 2 hours", TRUE, "More than 2 hours")} -> 30 to 60 mins | L12: =ROUND(calls[[#This Row],[Satisfaction Rating]],0) -> 4 | Q12: C0009 | R12: Female | S12: 25 | T12: Columbus
B13: Call_7280 | C13: C0010 | D13: 44 | E13: R03 | F13: 44929 | G13: 105 | H13: 2.9 | I13: =IF(MONTH(calls[[#This Row],[Date of Call]])<=6, YEAR(calls[[#This Row],[Date of Call]]), YEAR(calls[[#This Row],[Date of Call]])+1) -> 2023 | J13: =TEXT(calls[[#This Row],[Date of Call]],"DDDD") -> Tuesday | K13: {=_xlfn.IFS(calls[[#This Row],[Duration]]<=10,"Under 10 mins", calls[[#This Row],[Duration]]<=30, "10 to 30 mins", calls[[#This Row],[Duration]]<=60, "30 to 60 mins", calls[[#This Row],[Duration]]<=120, "1 to 2 hours", TRUE, "More than 2 hours")} -> 30 to 60 mins | L13: =ROUND(calls[[#This Row],[Satisfaction Rating]],0) -> 3 | Q13: C0010 | R13: Female | S13: 30 | T13: Cleveland
B14: Call_7281 | C14: C0011 | D14: 102 | E14: R02 | F14: 44929 | G14: 69 | H14: 4.9 | I14: =IF(MONTH(calls[[#This Row],[Date of Call]])<=6, YEAR(calls[[#This Row],[Date of Call]]), YEAR(calls[[#This Row],[Date of Call]])+1) -> 2023 | J14: =TEXT(calls[[#This Row],[Date of Call]],"DDDD") -> Tuesday | K14: {=_xlfn.IFS(calls[[#This Row],[Duration]]<=10,"Under 10 mins", calls[[#This Row],[Duration]]<=30, "10 to 30 mins", calls[[#This Row],[Duration]]<=60, "30 to 60 mins", calls[[#This Row],[Duration]]<=120, "1 to 2 hours", TRUE, "More than 2 hours")} -> 1 to 2 hours | L14: =ROUND(calls[[#This Row],[Satisfaction Rating]],0) -> 5 | Q14: C0011 | R14: Female | S14: 30 | T14: Cincinnati
B15: Call_7282 | C15: C0013 | D15: 135 | E15: R05 | F15: 44929 | G15: 46 | H15: 3.4 | I15: =IF(MONTH(calls[[#This Row],[Date of Call]])<=6, YEAR(calls[[#This Row],[Date of Call]]), YEAR(calls[[#This Row],[Date of Call]])+1) -> 2023 | J15: =TEXT(calls[[#This Row],[Date of Call]],"DDDD") -> Tuesday | K15: {=_xlfn.IFS(calls[[#This Row],[Duration]]<=10,"Under 10 mins", calls[[#This Row],[Duration]]<=30, "10 to 30 mins", calls[[#This Row],[Duration]]<=60, "30 to 60 mins", calls[[#This Row],[Duration]]<=120, "1 to 2 hours", TRUE, "More than 2 hours")} -> More than 2 hours | L15: =ROUND(calls[[#This Row],[Satisfaction Rating]],0) -> 3 | Q15: C0012 | R15: Female | S15: 28 | T15: Cincinnati
... B18: Call_7285 | C18: C0013 | D18: 48 | E18: R01 | F18: 44930 | G18: 68 | H18: 4.9 | I18: =IF(MONTH(calls[[#This Row],[Date of Call]])<=6, YEAR(calls[[#This Row],[Date of Call]]), YEAR(calls[[#This Row],[Date of Call]])+1) -> 2023 | J18: =TEXT(calls[[#This Row],[Date of Call]],"DDDD") -> Wednesday | K18: {=_xlfn.IFS(calls[[#This Row],[Duration]]<=10,"Under 10 mins", calls[[#This Row],[Duration]]<=30, "10 to 30 mins", calls[[#This Row],[Duration]]<=60, "30 to 60 mins", calls[[#This Row],[Duration]]<=120, "1 to 2 hours", TRUE, "More than 2 hours")} -> 30 to 60 mins | L18: =ROUND(calls[[#This Row],[Satisfaction Rating]],0) -> 5 | Q18: C0015 | R18: Female | S18: 43 | T18: Cleveland
B19: Call_7286 | C19: C0010 | D19: 176 | E19: R05 | F19: 44931 | G19: 24 | H19: 4.8 | I19: =IF(MONTH(calls[[#This Row],[Date of Call]])<=6, YEAR(calls[[#This Row],[Date of Call]]), YEAR(calls[[#This Row],[Date of Call]])+1) -> 2023 | J19: =TEXT(calls[[#This Row],[Date of Call]],"DDDD") -> Thursday | K19: {=_xlfn.IFS(calls[[#This Row],[Duration]]<=10,"Under 10 mins", calls[[#This Row],[Duration]]<=30, "10 to 30 mins", calls[[#This Row],[Duration]]<=60, "30 to 60 mins", calls[[#This Row],[Duration]]<=120, "1 to 2 hours", TRUE, "More than 2 hours")} -> More than 2 hours | L19: =ROUND(calls[[#This Row],[Satisfaction Rating]],0) -> 5
B20: Call_7287 | C20: C0010 | D20: 99 | E20: R01 | F20: 44931 | G20: 195 | H20: 3.9 | I20: =IF(MONTH(calls[[#This Row],[Date of Call]])<=6, YEAR(calls[[#This Row],[Date of Call]]), YEAR(calls[[#This Row],[Date of Call]])+1) -> 2023 | J20: =TEXT(calls[[#This Row],[Date of Call]],"DDDD") -> Thursday | K20: {=_xlfn.IFS(calls[[#This Row],[Duration]]<=10,"Under 10 mins", calls[[#This Row],[Duration]]<=30, "10 to 30 mins", calls[[#This Row],[Duration]]<=60, "30 to 60 mins", calls[[#This Row],[Duration]]<=120, "1 to 2 hours", TRUE, "More than 2 hours")} -> 1 to 2 hours | L20: =ROUND(calls[[#This Row],[Satisfaction Rating]],0) -> 4
B21: Call_7288 | C21: C0009 | D21: 28 | E21: R03 | F21: 44931 | G21: 28 | H21: 3.8 | I21: =IF(MONTH(calls[[#This Row],[Date of Call]])<=6, YEAR(calls[[#This Row],[Date of Call]]), YEAR(calls[[#This Row],[Date of Call]])+1) -> 2023 | J21: =TEXT(calls[[#This Row],[Date of Call]],"DDDD") -> Thursday | K21: {=_xlfn.IFS(calls[[#This Row],[Duration]]<=10,"Under 10 mins", calls[[#This Row],[Duration]]<=30, "10 to 30 mins", calls[[#This Row],[Duration]]<=60, "30 to 60 mins", calls[[#This Row],[Duration]]<=120, "1 to 2 hours", TRUE, "More than 2 hours")} -> 10 to 30 mins | L21: =ROUND(calls[[#This Row],[Satisfaction Rating]],0) -> 4
B22: Call_7289 | C22: C0007 | D22: 54 | E22: R02 | F22: 44931 | G22: 170 | H22: 4.3 | I22: =IF(MONTH(calls[[#This Row],[Date of Call]])<=6, YEAR(calls[[#This Row],[Date of Call]]), YEAR(calls[[#This Row],[Date of Call]])+1) -> 2023 | J22: =TEXT(calls[[#This Row],[Date of Call]],"DDDD") -> Thursday | K22: {=_xlfn.IFS(calls[[#This Row],[Duration]]<=10,"Under 10 mins", calls[[#This Row],[Duration]]<=30, "10 to 30 mins", calls[[#This Row],[Duration]]<=60, "30 to 60 mins", calls[[#This Row],[Duration]]<=120, "1 to 2 hours", TRUE, "More than 2 hours")} -> 30 to 60 mins | L22: =ROUND(calls[[#This Row],[Satisfaction Rating]],0) -> 4
B23: Call_7290 | C23: C0006 | D23: 48 | E23: R05 | F23: 44932 | G23: 30 | H23: 4.4 | I23: =IF(MONTH(calls[[#This Row],[Date of Call]])<=6, YEAR(calls[[#This Row],[Date of Call]]), YEAR(calls[[#This Row],[Date of Call]])+1) -> 2023 | J23: =TEXT(calls[[#This Row],[Date of Call]],"DDDD") -> Friday | K23: {=_xlfn.IFS(calls[[#This Row],[Duration]]<=10,"Under 10 mins", calls[[#This Row],[Duration]]<=30, "10 to 30 mins", calls[[#This Row],[Duration]]<=60, "30 to 60 mins", calls[[#This Row],[Duration]]<=120, "1 to 2 hours", TRUE, "More than 2 hours")} -> 30 to 60 mins | L23: =ROUND(calls[[#This Row],[Satisfaction Rating]],0) -> 4
B24: Call_7291 | C24: C0004 | D24: 128 | E24: R05 | F24: 44932 | G24: 72 | H24: 5 | I24: =IF(MONTH(calls[[#This Row],[Date of Call]])<=6, YEAR(calls[[#This Row],[Date of Call]]), YEAR(calls[[#This Row],[Date of Call]])+1) -> 2023 | J24: =TEXT(calls[[#This Row],[Date of Call]],"DDDD") -> Friday | K24: {=_xlfn.IFS(calls[[#This Row],[Duration]]<=10,"Under 10 mins", calls[[#This Row],[Duration]]<=30, "10 to 30 mins", calls[[#This Row],[Duration]]<=60, "30 to 60 mins", calls[[#This Row],[Duration]]<=120, "1 to 2 hours", TRUE, "More than 2 hours")} -> More than 2 hours | L24: =ROUND(calls[[#This Row],[Satisfaction Rating]],0) -> 5
B25: Call_7292 | C25: C0004 | D25: 38 | E25: R04 | F25: 44933 | G25: 92 | H25: 4.9 | I25: =IF(MONTH(calls[[#This Row],[Date of Call]])<=6, YEAR(calls[[#This Row],[Date of Call]]), YEAR(calls[[#This Row],[Date of Call]])+1) -> 2023 | J25: =TEXT(calls[[#This Row],[Date of Call]],"DDDD") -> Saturday | K25: {=_xlfn.IFS(calls[[#This Row],[Duration]]<=10,"Under 10 mins", calls[[#This Row],[Duration]]<=30, "10 to 30 mins", calls[[#This Row],[Duration]]<=60, "30 to 60 mins", calls[[#This Row],[Duration]]<=120, "1 to 2 hours", TRUE, "More than 2 hours")} -> 30 to 60 mins | L25: =ROUND(calls[[#This Row],[Satisfaction Rating]],0) -> 5
B26: Call_7293 | C26: C0003 | D26: 67 | E26: R04 | F26: 44934 | G26: 165 | H26: 4.5 | I26: =IF(MONTH(calls[[#This Row],[Date of Call]])<=6, YEAR(calls[[#This Row],[Date of Call]]), YEAR(calls[[#This Row],[Date of Call]])+1) -> 2023 | J26: =TEXT(calls[[#This Row],[Date of Call]],"DDDD") -> Sunday | K26: {=_xlfn.IFS(calls[[#This Row],[Duration]]<=10,"Under 10 mins", calls[[#This Row],[Duration]]<=30, "10 to 30 mins", calls[[#This Row],[Duration]]<=60, "30 to 60 mins", calls[[#This Row],[Duration]]<=120, "1 to 2 hours", TRUE, "More than 2 hours")} -> 1 to 2 hours | L26: =ROUND(calls[[#This Row],[Satisfaction Rating]],0) -> 5
B27: Call_7294 | C27: C0015 | D27: 58 | E27: R02 | F27: 44934 | G27: 140 | H27: 2.1 | I27: =IF(MONTH(calls[[#This Row],[Date of Call]])<=6, YEAR(calls[[#This Row],[Date of Call]]), YEAR(calls[[#This Row],[Date of Call]])+1) -> 2023 | J27: =TEXT(calls[[#This Row],[Date of Call]],"DDDD") -> Sunday | K27: {=_xlfn.IFS(calls[[#This Row],[Duration]]<=10,"Under 10 mins", calls[[#This Row],[Duration]]<=30, "10 to 30 mins", calls[[#This Row],[Duration]]<=60, "30 to 60 mins", calls[[#This Row],[Duration]]<=120, "1 to 2 hours", TRUE, "More than 2 hours")} -> 30 to 60 mins | L27: =ROUND(calls[[#This Row],[Satisfaction Rating]],0) -> 2
B28: Call_7295 | C28: C0010 | D28: 54 | E28: R01 | F28: 44934 | G28: 111 | H28: 3.3 | I28: =IF(MONTH(calls[[#This Row],[Date of Call]])<=6, YEAR(calls[[#This Row],[Date of Call]]), YEAR(calls[[#This Row],[Date of Call]])+1) -> 2023 | J28: =TEXT(calls[[#This Row],[Date of Call]],"DDDD") -> Sunday | K28: {=_xlfn.IFS(calls[[#This Row],[Duration]]<=10,"Under 10 mins", calls[[#This Row],[Duration]]<=30, "10 to 30 mins", calls[[#This Row],[Duration]]<=60, "30 to 60 mins", calls[[#This Row],[Duration]]<=120, "1 to 2 hours", TRUE, "More than 2 hours")} -> 30 to 60 mins | L28: =ROUND(calls[[#This Row],[Satisfaction Rating]],0) -> 3
B29: Call_7296 | C29: C0012 | D29: 28 | E29: R05 | F29: 44935 | G29: 63 | H29: 4.1 | I29: =IF(MONTH(calls[[#This Row],[Date of Call]])<=6, YEAR(calls[[#This Row],[Date of Call]]), YEAR(calls[[#This Row],[Date of Call]])+1) -> 2023 | J29: =TEXT(calls[[#This Row],[Date of Call]],"DDDD") -> Monday | K29: {=_xlfn.IFS(calls[[#This Row],[Duration]]<=10,"Under 10 mins", calls[[#This Row],[Duration]]<=30, "10 to 30 mins", calls[[#This Row],[Duration]]<=60, "30 to 60 mins", calls[[#This Row],[Duration]]<=120, "1 to 2 hours", TRUE, "More than 2 hours")} -> 10 to 30 mins | L29: =ROUND(calls[[#This Row],[Satisfaction Rating]],0) -> 4
B30: Call_7297 | C30: C0002 | D30: 73 | E30: R05 | F30: 44935 | G30: 80 | H30: 4.2 | I30: =IF(MONTH(calls[[#This Row],[Date of Call]])<=6, YEAR(calls[[#This Row],[Date of Call]]), YEAR(calls[[#This Row],[Date of Call]])+1) -> 2023 | J30: =TEXT(calls[[#This Row],[Date of Call]],"DDDD") -> Monday | K30: {=_xlfn.IFS(calls[[#This Row],[Duration]]<=10,"Under 10 mins", calls[[#This Row],[Duration]]<=30, "10 to 30 mins", calls[[#This Row],[Duration]]<=60, "30 to 60 mins", calls[[#This Row],[Duration]]<=120, "1 to 2 hours", TRUE, "More than 2 hours")} -> 1 to 2 hours | L30: =ROUND(calls[[#This Row],[Satisfaction Rating]],0) -> 4
... B1003: Call_8270 | C1003: C0009 | D1003: 114 | E1003: R01 | F1003: 45291 | G1003: 40 | H1003: 3.9 | I1003: =IF(MONTH(calls[[#This Row],[Date of Call]])<=6, YEAR(calls[[#This Row],[Date of Call]]), YEAR(calls[[#This Row],[Date of Call]])+1) -> 2024 | J1003: =TEXT(calls[[#This Row],[Date of Call]],"DDDD") -> Sunday | K1003: {=_xlfn.IFS(calls[[#This Row],[Duration]]<=10,"Under 10 mins", calls[[#This Row],[Duration]]<=30, "10 to 30 mins", calls[[#This Row],[Duration]]<=60, "30 to 60 mins", calls[[#This Row],[Duration]]<=120, "1 to 2 hours", TRUE, "More than 2 hours")} -> 1 to 2 hours | L1003: =ROUND(calls[[#This Row],[Satisfaction Rating]],0) -> 4
